Workbook

Sheet student_performance_analysis
B2: Student ID | C2: Gender | D2: Hours Studied | E2: Attendance | F2: Assignment completed | G2: Actual Score | H2: Predicted Score | T2: Hours Studied | U2: Distribution | W2: Score Range | X2: Distribution | AC2: Row Labels | AD2: Max of Hours Studied
B3: 1 | C3: Female | D3: 6.3 | E3: 61 | F3: 6 | G3: 50.9 | H3: =($G$3+($V$51*D3)+(E3*$V$52)+($V$53*F3)) -> 69.063496 | J3: =COUNTIF(C3:C52,C45) -> 25 | T3: 5-6.9 | U3: 10 | W3: 50-61 | X3: 14 | AC3: Female | AD3: 16.7
B4: 2 | C4: Male | D4: 7.6 | E4: 62 | F4: 7 | G4: 51.8 | H4: =($G$3+($V$51*D4)+(E4*$V$52)+($V$53*F4)) -> 69.990059 | J4: =COUNTIF(C3:C52,C4) -> 25 | T4: 7.0-9 | U4: 10 | W4: 62-71 | X4: 11 | AC4: Male | AD4: 15.4
B5: 3 | C5: Female | D5: 8.9 | E5: 63 | F5: 8 | G5: 52.7 | H5: =($G$3+($V$51*D5)+(E5*$V$52)+($V$53*F5)) -> 70.916622 | T5: 9.1-11 | U5: 5 | W5: 72-81 | X5: 11 | AC5: Grand Total | AD5: 16.7
B6: 4 | C6: Male | D6: 10.2 | E6: 64 | F6: 9 | G6: 53.6 | H6: =($G$3+($V$51*D6)+(E6*$V$52)+($V$53*F6)) -> 71.843186 | T6: 11.1-13 | U6: 10 | W6: 82-91 | X6: 11
B7: 5 | C7: Female | D7: 11.5 | E7: 65 | F7: 10 | G7: 54.5 | H7: =($G$3+($V$51*D7)+(E7*$V$52)+($V$53*F7)) -> 72.769749 | T7: 13.1-15 | U7: 5 | W7: 92-100 | X7: 3 | AC7: Row Labels | AD7: Max of Attendance
B8: 6 | C8: Male | D8: 12.8 | E8: 66 | F8: 11 | G8: 55.4 | H8: =($G$3+($V$51*D8)+(E8*$V$52)+($V$53*F8)) -> 73.696312 | T8: 15.1-17 | U8: 10 | AC8: Female | AD8: 99
B9: 7 | C9: Female | D9: 14.1 | E9: 67 | F9: 12 | G9: 56.3 | H9: =($G$3+($V$51*D9)+(E9*$V$52)+($V$53*F9)) -> 74.622875 | AC9: Male | AD9: 98
B10: 8 | C10: Male | D10: 15.4 | E10: 68 | F10: 13 | G10: 57.2 | H10: =($G$3+($V$51*D10)+(E10*$V$52)+($V$53*F10)) -> 75.549438 | T10: Attendance | U10: Distirbution | W10: Assignment | X10: Distribution | AC10: Grand Total | AD10: 99
B11: 9 | C11: Female | D11: 16.7 | E11: 69 | F11: 14 | G11: 58.1 | H11: =($G$3+($V$51*D11)+(E11*$V$52)+($V$53*F11)) -> 76.476001 | T11: 60-71 | U11: 21 | W11: 5 - 7.0 | X11: 15
B12: 10 | C12: Male | D12: 5 | E12: 70 | F12: 5 | G12: 59 | H12: =($G$3+($V$51*D12)+(E12*$V$52)+($V$53*F12)) -> 70.571891 | T12: 72-81 | U12: 10 | W12: 7.1-9 | X12: 10 | AC12: Row Labels | AD12: Min of Attendance
B13: 11 | C13: Female | D13: 6.3 | E13: 71 | F13: 6 | G13: 59.9 | H13: =($G$3+($V$51*D13)+(E13*$V$52)+($V$53*F13)) -> 71.498454 | T13: 82-91 | U13: 10 | W13: 9.1-11 | X13: 10 | AC13: Female | AD13: 61
B14: 12 | C14: Male | D14: 7.6 | E14: 72 | F14: 7 | G14: 60.8 | H14: =($G$3+($V$51*D14)+(E14*$V$52)+($V$53*F14)) -> 72.425018 | T14: 92-100 | U14: 9 | W14: 11.1-13 | X14: 10 | AC14: Male | AD14: 60
B15: 13 | C15: Female | D15: 8.9 | E15: 73 | F15: 8 | G15: 61.7 | H15: =($G$3+($V$51*D15)+(E15*$V$52)+($V$53*F15)) -> 73.351581 | J15: Metric | K15: Average | W15: 13.1-15 | X15: 5 | AC15: Grand Total | AD15: 60
B16: 14 | C16: Male | D16: 10.2 | E16: 74 | F16: 9 | G16: 62.6 | H16: =($G$3+($V$51*D16)+(E16*$V$52)+($V$53*F16)) -> 74.278144 | J16: Hours Studied | K16: 10.9
B17: 15 | C17: Female | D17: 11.5 | E17: 75 | F17: 10 | G17: 63.5 | H17: =($G$3+($V$51*D17)+(E17*$V$52)+($V$53*F17)) -> 75.204707 | J17: Attendance (%) | K17: 76.7 | Z17: Row Labels | AA17: Count of Student ID | AC17: Row Labels | AD17: Average of Score
B18: 16 | C18: Male | D18: 12.8 | E18: 76 | F18: 11 | G18: 64.4 | H18: =($G$3+($V$51*D18)+(E18*$V$52)+($V$53*F18)) -> 76.13127 | J18: Assignment | K18: 9.5 | T18: Row Labels | U18: Count of Student ID | Z18: Female | AA18: 25 | AC18: Female | AD18: 72.5
B19: 17 | C19: Female | D19: 14.1 | E19: 77 | F19: 12 | G19: 65.3 | H19: =($G$3+($V$51*D19)+(E19*$V$52)+($V$53*F19)) -> 77.057834 | J19: Score (%) | K19: 72.1 | T19: Female | U19: 25 | Z19: Male | AA19: 25 | AC19: Male | AD19: 71.6
B20: 18 | C20: Male | D20: 15.4 | E20: 78 | F20: 13 | G20: 66.2 | H20: =($G$3+($V$51*D20)+(E20*$V$52)+($V$53*F20)) -> 77.984397 | T20: Male | U20: 25 | Z20: Grand Total | AA20: 50 | AC20: Grand Total | AD20: 72.05
B21: 19 | C21: Female | D21: 16.7 | E21: 79 | F21: 14 | G21: 67.1 | H21: =($G$3+($V$51*D21)+(E21*$V$52)+($V$53*F21)) -> 78.91096 | J21: Performance | K21: No. of Student | T21: Grand Total | U21: 50
B22: 20 | C22: Male | D22: 5 | E22: 80 | F22: 5 | G22: 68 | H22: =($G$3+($V$51*D22)+(E22*$V$52)+($V$53*F22)) -> 73.00685 | J22: High Performer (85-100) | K22: 11 | Z22: Row Labels | AA22: Average of Hours Studied | AC22: Row Labels | AD22: Min of Score
B23: 21 | C23: Female | D23: 6.3 | E23: 81 | F23: 6 | G23: 68.9 | H23: =($G$3+($V$51*D23)+(E23*$V$52)+($V$53*F23)) -> 73.933413 | J23: Medium Performer (70-84) | K23: 16 | Z23: Female | AA23: 11.5 | AC23: Female | AD23: 50.9
B24: 22 | C24: Male | D24: 7.6 | E24: 82 | F24: 7 | G24: 69.8 | H24: =($G$3+($V$51*D24)+(E24*$V$52)+($V$53*F24)) -> 74.859976 | J24: Low Performer (50-69) | K24: 23 | Z24: Male | AA24: 10.2 | AC24: Male | AD24: 50
B25: 23 | C25: Female | D25: 8.9 | E25: 83 | F25: 8 | G25: 70.7 | H25: =($G$3+($V$51*D25)+(E25*$V$52)+($V$53*F25)) -> 75.786539 | Z25: Average | AA25: 10.85 | AC25: Grand Total | AD25: 50
B26: 24 | C26: Male | D26: 10.2 | E26: 84 | F26: 9 | G26: 71.6 | H26: =($G$3+($V$51*D26)+(E26*$V$52)+($V$53*F26)) -> 76.713102
B27: 25 | C27: Female | D27: 11.5 | E27: 85 | F27: 10 | G27: 72.5 | H27: =($G$3+($V$51*D27)+(E27*$V$52)+($V$53*F27)) -> 77.639666 | K27: Hours Studied | L27: Attendance | M27: Assignment completed | N27: Actual Score | O27: Predicted Score | Z27: Row Labels | AA27: Average of Attendance | AC27: Row Labels | AD27: Max of Score
B28: 26 | C28: Male | D28: 12.8 | E28: 86 | F28: 11 | G28: 73.4 | H28: =($G$3+($V$51*D28)+(E28*$V$52)+($V$53*F28)) -> 78.566229 | J28: Hours Studied | K28: 1 | Z28: Female | AA28: 77 | AC28: Female | AD28: 94.1
B29: 27 | C29: Female | D29: 14.1 | E29: 87 | F29: 12 | G29: 74.3 | H29: =($G$3+($V$51*D29)+(E29*$V$52)+($V$53*F29)) -> 79.492792 | J29: Attendance | K29: 0.2165719 | L29: 1 | Z29: Male | AA29: 76.4 | AC29: Male | AD29: 93.2
B30: 28 | C30: Male | D30: 15.4 | E30: 88 | F30: 13 | G30: 75.2 | H30: =($G$3+($V$51*D30)+(E30*$V$52)+($V$53*F30)) -> 80.419355 | J30: Assignment completed | K30: 1 | L30: 0.2165719 | M30: 1 | Z30: Average | AA30: 76.7 | AC30: Grand Total | AD30: 94.1
B31: 29 | C31: Female | D31: 16.7 | E31: 89 | F31: 14 | G31: 76.1 | H31: =($G$3+($V$51*D31)+(E31*$V$52)+($V$53*F31)) -> 81.345918 | J31: Actual Score | K31: 0.1990373 | L31: 0.25423675 | M31: 0.1990373 | N31: 1
B32: 30 | C32: Male | D32: 5 | E32: 90 | F32: 5 | G32: 77 | H32: =($G$3+($V$51*D32)+(E32*$V$52)+($V$53*F32)) -> 75.441808 | J32: Predicted Score | K32: 0.67719446 | L32: 0.8650023 | M32: 0.67719446 | N32: 0.29391454 | O32: 1 | Z32: Row Labels | AA32: Average of Assignment completed | AC32: Row Labels | AD32: Min of Hours Studied
B33: 31 | C33: Female | D33: 6.3 | E33: 91 | F33: 6 | G33: 77.9 | H33: =($G$3+($V$51*D33)+(E33*$V$52)+($V$53*F33)) -> 76.368371 | Z33: Female | AA33: 10 | AC33: Female | AD33: 6.3
B34: 32 | C34: Male | D34: 7.6 | E34: 92 | F34: 7 | G34: 78.8 | H34: =($G$3+($V$51*D34)+(E34*$V$52)+($V$53*F34)) -> 77.294935 | AA34: 9 | AD34: 5
B35: 33 | C35: Female | D35: 8.9 | E35: 93 | F35: 8 | G35: 79.7 | H35: =($G$3+($V$51*D35)+(E35*$V$52)+($V$53*F35)) -> 78.221498 | AD35: 5
B36: 34 | C36: Male | D36: 10.2 | E36: 94 | F36: 9 | G36: 80.6 | H36: =($G$3+($V$51*D36)+(E36*$V$52)+($V$53*F36)) -> 79.148061
B37: 35 | C37: Female | D37: 11.5 | E37: 95 | F37: 10 | G37: 81.5 | H37: =($G$3+($V$51*D37)+(E37*$V$52)+($V$53*F37)) -> 80.074624 | V37: 0.29391454
B38: 36 | C38: Male | D38: 12.8 | E38: 96 | F38: 11 | G38: 82.4 | H38: =($G$3+($V$51*D38)+(E38*$V$52)+($V$53*F38)) -> 81.001187 | K38: Row Labels | L38: Average of Actual Score | V38: 0.086385757
B39: 37 | C39: Female | D39: 14.1 | E39: 97 | F39: 12 | G39: 83.3 | H39: =($G$3+($V$51*D39)+(E39*$V$52)+($V$53*F39)) -> 81.92775 | K39: Female | L39: 72.5 | V39: 0.026231959
B40: 38 | C40: Male | D40: 15.4 | E40: 98 | F40: 13 | G40: 84.2 | H40: =($G$3+($V$51*D40)+(E40*$V$52)+($V$53*F40)) -> 82.854314 | K40: Male | L40: 71.6 | V40: Predicted Score
B41: 39 | C41: Female | D41: 16.7 | E41: 99 | F41: 14 | G41: 85.1 | H41: =($G$3+($V$51*D41)+(E41*$V$52)+($V$53*F41)) -> 83.780877 | K41: Grand Total | L41: 72.05
...

Sheet Dashboard
N4: =student_performance_analysis!K27 -> Hours Studied | O4: =student_performance_analysis!L27 -> Attendance | P4: =student_performance_analysis!M27 -> Assignment completed | Q4: =student_performance_analysis!N27 -> Actual Score
M5: Hours Studied | N5: =student_performance_analysis!K28 -> 1 | O5: =student_performance_analysis!L28 -> 0 | P5: =student_performance_analysis!M28 -> 0 | Q5: =student_performance_analysis!N28 -> 0
M6: Attendance | N6: =student_performance_analysis!K29 -> 0.2165719 | O6: =student_performance_analysis!L29 -> 1 | P6: =student_performance_analysis!M29 -> 0 | Q6: =student_performance_analysis!N29 -> 0
M7: Assignment | N7: =student_performance_analysis!K30 -> 1 | O7: =student_performance_analysis!L30 -> 0.2165719 | P7: =student_performance_analysis!M30 -> 1 | Q7: =student_performance_analysis!N30 -> 0
M8: Score | N8: =student_performance_analysis!K31 -> 0.1990373 | O8: =student_performance_analysis!L31 -> 0.25423675 | P8: =student_performance_analysis!M31 -> 0.1990373 | Q8: =student_performance_analysis!N31 -> 1
